Workbook

Sheet Cover
C4: FERRARI N.V.
C6: Credit Application: Integrated Financial Model
C7: Ferrari Residential Complex Miami | €1,100m annuity term loan
C11: Business Plan and Credit Assessment, 2022A-2030F | N11: EM032 Banking, IES FSV UK
C12: Matúš Balko | N12: November 2025
C13: Hypothetical case study: the Ferrari Residential Complex Miami project, its costs, financing and loan terms are made up for an academic exercise. Ferrari N.V. has not announced such a project. Historical 2022-2024 figures are Ferrari's reported data.
C14: Table of Contents | K14: Model Checks
C16: Inputs | K16: Does the balance sheet balance (standalone)? | N16: =IF(SUMPRODUCT(ABS(Model!D84:L84))<0.01,1,0) -> 1
C17: Income Statement | K17: Does the balance sheet balance (with project)? | N17: =IF(SUMPRODUCT(ABS(Model!D355:L355))<0.01,1,0) -> 1
C18: Revenue Build: Shipments and Revenue per Unit | K18: Is cash negative in any year? | N18: =IF(MIN(Model!D67:L67,Model!D345:L345)<0,1,0) -> 0
C19: Balance Sheet | K19: Annuity instalment matches Excel PMT? | N19: =IF(ABS(Model!F285)<0.000001,1,0) -> 1
C20: Cash Flow Statement | K20: Project loan fully repaid by Q4 2030? | N20: =IF(ABS(Model!J316)<0.01,1,0) -> 1
C21: Financial Analysis: Ferrari Standalone
C22: Working Capital Schedule
C23: Fixed Asset Schedule: PP&E and Intangible Assets
C24: Financing Schedule: Debt, Cash and Equity
C25: Residential Project: Ferrari Residential Complex Miami
C26: Project Loan: Annuity Repayment Schedule
C27: Pro-forma Statements: Ferrari with Project
C28: Credit Metrics: Standalone vs. with Project
C31: Key Figures | K31: Base-Case Credit Profile (2025F-2030F)
C33: Project loan amount (€m) | H33: =Model!F277 -> 1100 | K33: Peak net debt / EBITDA (standalone) | N33: =MAX(Model!G383:L383) -> 0.48709635
C34: Interest rate (fixed, p.a.) | H34: =Model!F278 -> 0.05 | K34: Peak net debt / EBITDA (with project) | N34: =MAX(Model!G390:L390) -> 0.71763682
C35: Quarterly annuity instalment (€m) | H35: =Model!F283 -> 145.34645 | K35: Minimum EBITDA / interest (with project) | N35: =MIN(Model!G391:L391) -> 16.102114
C36: Total interest over loan life (€m) | H36: =Model!F291 -> 154.0216 | K36: Minimum project DSCR (repayment years) | N36: =MIN(Model!G294:L294) -> 1.1808581
C37: Project IRR (unlevered, pre-tax) | H37: =Model!F262 -> 0.085332527 | K37: Lowest cash balance with project (€m) | N37: =MIN(Model!G345:L345) -> 1822.9143
C38: Break-even price incl. financing (€ per m²) | H38: =Model!F265 -> 17544.684
C41: Notes
C42: All figures in € millions unless stated. Historical data 2022-2024: Ferrari N.V. consolidated financial statements (Form 20-F), IFRS.
C43: Forecast drivers and project assumptions are on the Inputs sheet. Cash is derived from the cash flow statement, so the balance sheet balances without a plug.
C44: The project loan is a fixed-rate annuity: interest-only during construction, then eight equal quarterly instalments.
C45: Project interest is expensed through the income statement. This is a simplification, as under IAS 23 it would be capitalised into inventory and released on handover.
C46: Hypothetical case study: the Miami residential project and the loan are fictional and were made up for an academic exercise. Not affiliated with or endorsed by Ferrari N.V.

Sheet Inputs
B1: Ferrari N.V. | Credit Application Model
B3: Inputs: Forecast Drivers and Project Assumptions
B5: All figures in € millions unless stated | L5: Forecast
F6: Input | G6: 2025 | H6: 2026 | I6: 2027 | J6: 2028 | K6: 2029 | L6: 2030 | N6: Basis and source
B8: REVENUE: SHIPMENTS AND NET REVENUE PER UNIT
B9: EMEA shipment growth | C9: % y/y | G9: 0.01 | H9: 0.01 | I9: 0.01 | J9: 0.01 | K9: 0.01 | L9: 0.01 | N9: Volumes kept broadly stable (Ferrari CMD Oct-2025: growth driven by price and mix, not volume)
B10: Americas shipment growth | C10: % y/y | G10: 0.02 | H10: 0.02 | I10: 0.02 | J10: 0.02 | K10: 0.02 | L10: 0.02 | N10: Strongest region (2023-24 average +7.8% y/y), moderated
B11: Mainland China, Hong Kong and Taiwan shipment growth | C11: % y/y | G11: 0.02 | H11: 0.02 | I11: 0.02 | J11: 0.02 | K11: 0.02 | L11: 0.02 | N11: Gradual recovery from low 2024 base (-22.0% y/y)
B12: Rest of APAC shipment growth | C12: % y/y | G12: 0.01 | H12: 0.01 | I12: 0.01 | J12: 0.01 | K12: 0.01 | L12: 0.01 | N12: Volumes kept broadly stable
B13: Growth in net revenue per unit shipped | C13: % y/y | G13: 0.05 | H13: 0.035 | I13: 0.035 | J13: 0.035 | K13: 0.035 | L13: 0.035 | N13: Price, mix and personalisation. Gives about €7.1bn of revenue in 2025 (guidance of at least €7.1bn) and about €9.0bn in 2030 (Ferrari target, about 5% a year)
B15: OPERATING COSTS AND TAX
B16: Cost of sales | C16: % revenue | G16: 0.495 | H16: 0.493 | I16: 0.491 | J16: 0.489 | K16: 0.487 | L16: 0.485 | N16: Gradual improvement from 49.9% (2024A) toward Ferrari's 2030 target of an EBITDA margin of at least 40%
B17: Selling, general and administrative costs | C17: % revenue | G17: 0.084 | H17: 0.084 | I17: 0.084 | J17: 0.084 | K17: 0.084 | L17: 0.084 | N17: 2024A level (2022-24 range 7.7-8.4%)
B18: Research and development costs | C18: % revenue | G18: 0.132 | H18: 0.132 | I18: 0.132 | J18: 0.132 | K18: 0.132 | L18: 0.132 | N18: Close to 2024A (13.4%) as EV and new-model spending continues
B19: Other expenses, net | C19: % revenue | G19: 0.002 | H19: 0.002 | I19: 0.002 | J19: 0.002 | K19: 0.002 | L19: 0.002 | N19: 2024A level
B20: Result from investments | C20: €m | G20: 8 | H20: 8 | I20: 8 | J20: 8 | K20: 8 | L20: 8 | N20: Held at about the 2024A level (€8.2m)
B21: Effective tax rate | C21: % EBT | G21: 0.2 | H21: 0.2 | I21: 0.2 | J21: 0.2 | K21: 0.2 | L21: 0.2 | N21: 2022-24 average 20.3% (Italian patent box benefit)
B22: Non-controlling interests | C22: % net profit | G22: 0.003 | H22: 0.003 | I22: 0.003 | J22: 0.003 | K22: 0.003 | L22: 0.003 | N22: 2024A: 0.3%
B24: WORKING CAPITAL
B25: Trade receivables | C25: days | G25: 19 | H25: 19 | I25: 19 | J25: 19 | K25: 19 | L25: 19 | N25: 2024A: 19.1 days of revenue
B26: Inventories | C26: days | G26: 119 | H26: 119 | I26: 119 | J26: 119 | K26: 119 | L26: 119 | N26: 2024A: 119.3 days of cost of sales
B27: Trade payables | C27: days | G27: 104 | H27: 104 | I27: 104 | J27: 104 | K27: 104 | L27: 104 | N27: 2024A: 103.7 days of cost of sales
B28: Receivables from financing activities | C28: % revenue | G28: 0.249 | H28: 0.249 | I28: 0.249 | J28: 0.249 | K28: 0.249 | L28: 0.249 | N28: 2024A: 24.9%. Client and dealer financing grows with sales
B29: Other current assets | C29: % revenue | G29: 0.021 | H29: 0.021 | I29: 0.021 | J29: 0.021 | K29: 0.021 | L29: 0.021 | N29: 2024A: 2.1%
B30: Other liabilities | C30: % revenue | G30: 0.166 | H30: 0.166 | I30: 0.166 | J30: 0.166 | K30: 0.166 | L30: 0.166 | N30: 2024A: 16.6%, includes client advances and deferred income
B31: Provisions | C31: % revenue | G31: 0.031 | H31: 0.031 | I31: 0.031 | J31: 0.031 | K31: 0.031 | L31: 0.031 | N31: 2024A: 3.1%
B32: Days in period | C32: days | F32: 365
B33: Goodwill, investments, tax balances, deferred taxes, employee benefits and other financial liabilities are held at 2024A levels
B35: CAPITAL EXPENDITURE, DEPRECIATION AND AMORTISATION
B36: Capital expenditure on PP&E | C36: % revenue | G36: 0.058 | H36: 0.058 | I36: 0.058 | J36: 0.058 | K36: 0.058 | L36: 0.058 | N36: Total capex of 11.5% of revenue, about €4.7bn over 2026-30 (Ferrari target)
B37: Capital expenditure on intangible assets (capitalised development) | C37: % revenue | G37: 0.057 | H37: 0.057 | I37: 0.057 | J37: 0.057 | K37: 0.057 | L37: 0.057 | N37: See above (2024A: 7.2% PP&E + 7.6% intangibles during the e-building peak)
B38: Depreciation | C38: % opening PP&E | G38: 0.145 | H38: 0.145 | I38: 0.145 | J38: 0.145 | K38: 0.145 | L38: 0.145 | N38: Implied 2024A roll-forward: 14.5%
B39: Amortisation | C39: % opening intangibles | G39: 0.268 | H39: 0.268 | I39: 0.268 | J39: 0.268 | K39: 0.268 | L39: 0.268 | N39: Implied 2024A roll-forward: 26.8%
B41: FINANCING AND SHAREHOLDER RETURNS
B42: Change in existing debt | C42: €m | G42: 0 | H42: 0 | I42: 0 | J42: 0 | K42: 0 | L42: 0 | N42: Maturities refinanced, no new corporate debt in the base case
B43: Interest rate on existing debt | C43: % opening debt | G43: 0.044 | H43: 0.044 | I43: 0.044 | J43: 0.044 | K43: 0.044 | L43: 0.044 | N43: Keeps financial expenses at the 2024A level (€146m, about 4.4% of year-end 2024 debt)
B44: Interest income on cash | C44: % opening cash | G44: 0.02 | H44: 0.02 | I44: 0.02 | J44: 0.02 | K44: 0.02 | L44: 0.02 | N44: Euro deposit rates of about 2%. Excludes FX and hedging gains included in historical financial income
B45: Dividend payout | C45: % prior-yr profit | G45: 0.35 | H45: 0.35 | I45: 0.4 | J45: 0.4 | K45: 0.4 | L45: 0.4 | N45: 35% of prior-year profit, raised to 40% from 2027 (Ferrari Capital Markets Day, October 2025)
B46: Share repurchases | C46: €m | G46: 500 | H46: 700 | I46: 700 | J46: 700 | K46: 700 | L46: 700 | N46: Ferrari target of about €3.5bn of buybacks in 2026-30. 2025 in line with the 2022-24 average (€479m)
B48: RESIDENTIAL PROJECT: MIAMI
...

Sheet Model
B1: Ferrari N.V. | Credit Application Model
B3: Income Statement
B4: All figures in € millions unless stated | F4: Actual | L4: Forecast
D5: 2022 | E5: =D5+1 -> 2023 | F5: =E5+1 -> 2024 | G5: =F5+1 -> 2025 | H5: =G5+1 -> 2026 | I5: =H5+1 -> 2027 | J5: =I5+1 -> 2028 | K5: =J5+1 -> 2029 | L5: =K5+1 -> 2030
B6: Net revenues | D6: 5095.254 | E6: 5970.146 | F6: 6676.668 | G6: =G48 -> 7106.9366 | H6: =H48 -> 7457.0329 | I6: =I48 -> 7824.5544 | J6: =J48 -> 8210.3775 | K6: =K48 -> 8615.4232 | L6: =L48 -> 9040.6594
B7: Cost of sales | D7: -2648.953 | E7: -2995.877 | F7: -3329.483 | G7: =-G6*Inputs!G16 -> -3517.9336 | H7: =-H6*Inputs!H16 -> -3676.3172 | I7: =-I6*Inputs!I16 -> -3841.8562 | J7: =-J6*Inputs!J16 -> -4014.8746 | K7: =-K6*Inputs!K16 -> -4195.7111 | L7: =-L6*Inputs!L16 -> -4384.7198
B8: Gross profit | D8: =SUM(D6:D7) -> 2446.301 | E8: =SUM(E6:E7) -> 2974.269 | F8: =SUM(F6:F7) -> 3347.185 | G8: =SUM(G6:G7) -> 3589.003 | H8: =SUM(H6:H7) -> 3780.7157 | I8: =SUM(I6:I7) -> 3982.6982 | J8: =SUM(J6:J7) -> 4195.5029 | K8: =SUM(K6:K7) -> 4419.7121 | L8: =SUM(L6:L7) -> 4655.9396
B9: Selling, general and administrative costs | D9: -427.974 | E9: -462.58 | F9: -561.144 | G9: =-G6*Inputs!G17 -> -596.98267 | H9: =-H6*Inputs!H17 -> -626.39076 | I9: =-I6*Inputs!I17 -> -657.26257 | J9: =-J6*Inputs!J17 -> -689.67171 | K9: =-K6*Inputs!K17 -> -723.69555 | L9: =-L6*Inputs!L17 -> -759.41539
B10: Research and development costs | D10: -775.572 | E10: -881.559 | F10: -894.092 | G10: =-G6*Inputs!G18 -> -938.11563 | H10: =-H6*Inputs!H18 -> -984.32834 | I10: =-I6*Inputs!I18 -> -1032.8412 | J10: =-J6*Inputs!J18 -> -1083.7698 | K10: =-K6*Inputs!K18 -> -1137.2359 | L10: =-L6*Inputs!L18 -> -1193.367
B11: Other expenses, net | D11: -21.548 | E11: -18.898 | F11: -12.443 | G11: =-G6*Inputs!G19 -> -14.213873 | H11: =-H6*Inputs!H19 -> -14.914066 | I11: =-I6*Inputs!I19 -> -15.649109 | J11: =-J6*Inputs!J19 -> -16.420755 | K11: =-K6*Inputs!K19 -> -17.230846 | L11: =-L6*Inputs!L19 -> -18.081319
B12: Result from investments | D12: 6.175 | E12: 6.137 | F12: 8.245 | G12: =Inputs!G20 -> 8 | H12: =Inputs!H20 -> 8 | I12: =Inputs!I20 -> 8 | J12: =Inputs!J20 -> 8 | K12: =Inputs!K20 -> 8 | L12: =Inputs!L20 -> 8
B13: Operating profit (EBIT) | D13: =SUM(D8,D9:D12) -> 1227.382 | E13: =SUM(E8,E9:E12) -> 1617.369 | F13: =SUM(F8,F9:F12) -> 1887.751 | G13: =SUM(G8,G9:G12) -> 2047.6908 | H13: =SUM(H8,H9:H12) -> 2163.0825 | I13: =SUM(I8,I9:I12) -> 2284.9453 | J13: =SUM(J8,J9:J12) -> 2413.6406 | K13: =SUM(K8,K9:K12) -> 2549.5498 | L13: =SUM(L8,L9:L12) -> 2693.0758
B14: Financial income | D14: 83.858 | E14: 132.319 | F14: 147.1 | G14: =G217 -> 34.84428 | H14: =H217 -> 41.208287 | I14: =I217 -> 45.023334 | J14: =J217 -> 48.122671 | K14: =K217 -> 52.171339 | L14: =L217 -> 57.291011
B15: Financial expenses | D15: -133.474 | E15: -147.334 | F15: -145.895 | G15: =-G213 -> -147.48307 | H15: =-H213 -> -147.48307 | I15: =-I213 -> -147.48307 | J15: =-J213 -> -147.48307 | K15: =-K213 -> -147.48307 | L15: =-L213 -> -147.48307
B16: Profit before taxes | D16: =SUM(D13,D14:D15) -> 1177.766 | E16: =SUM(E13,E14:E15) -> 1602.354 | F16: =SUM(F13,F14:F15) -> 1888.956 | G16: =SUM(G13,G14:G15) -> 1935.052 | H16: =SUM(H13,H14:H15) -> 2056.8077 | I16: =SUM(I13,I14:I15) -> 2182.4856 | J16: =SUM(J13,J14:J15) -> 2314.2802 | K16: =SUM(K13,K14:K15) -> 2454.2381 | L16: =SUM(L13,L14:L15) -> 2602.8838
B17: Income tax expense | D17: -238.472 | E17: -344.897 | F17: -363.043 | G17: =-G16*Inputs!G21 -> -387.0104 | H17: =-H16*Inputs!H21 -> -411.36154 | I17: =-I16*Inputs!I21 -> -436.49712 | J17: =-J16*Inputs!J21 -> -462.85604 | K17: =-K16*Inputs!K21 -> -490.84762 | L17: =-L16*Inputs!L21 -> -520.57676
B18: Net profit | D18: =SUM(D16:D17) -> 939.294 | E18: =SUM(E16:E17) -> 1257.457 | F18: =SUM(F16:F17) -> 1525.913 | G18: =SUM(G16:G17) -> 1548.0416 | H18: =SUM(H16:H17) -> 1645.4462 | I18: =SUM(I16:I17) -> 1745.9885 | J18: =SUM(J16:J17) -> 1851.4242 | K18: =SUM(K16:K17) -> 1963.3905 | L18: =SUM(L16:L17) -> 2082.307
B19: Attributable to non-controlling interests | D19: 6.68 | E19: 5.409 | F19: 4.036 | G19: =G18*Inputs!G22 -> 4.6441248 | H19: =H18*Inputs!H22 -> 4.9363385 | I19: =I18*Inputs!I22 -> 5.2379654 | J19: =J18*Inputs!J22 -> 5.5542725 | K19: =K18*Inputs!K22 -> 5.8901715 | L19: =L18*Inputs!L22 -> 6.2469211
B20: Attributable to owners of the parent | D20: =D18-D19 -> 932.614 | E20: =E18-E19 -> 1252.048 | F20: =F18-F19 -> 1521.877 | G20: =G18-G19 -> 1543.3975 | H20: =H18-H19 -> 1640.5098 | I20: =I18-I19 -> 1740.7505 | J20: =J18-J19 -> 1845.8699 | K20: =K18-K19 -> 1957.5003 | L20: =L18-L19 -> 2076.0601
B21: Memo:
B22: Depreciation and amortisation | D22: 546.225 | E22: 662.305 | F22: 666.777 | G22: =G198 -> 679.41163 | H22: =H198 -> 698.28058 | I22: =I198 -> 723.00728 | J22: =J198 -> 752.41652 | K22: =K198 -> 785.68944 | L22: =L198 -> 822.26701
B23: EBITDA | D23: =D13+D22 -> 1773.607 | E23: =E13+E22 -> 2279.674 | F23: =F13+F22 -> 2554.528 | G23: =G13+G22 -> 2727.1024 | H23: =H13+H22 -> 2861.3631 | I23: =I13+I22 -> 3007.9526 | J23: =J13+J22 -> 3166.0571 | K23: =K13+K22 -> 3335.2393 | L23: =L13+L22 -> 3515.3429
B24: Assumptions:
B25: Revenue growth | E25: =E6/D6-1 -> 0.17170724 | F25: =F6/E6-1 -> 0.1183425 | G25: =G6/F6-1 -> 0.064443608 | H25: =H6/G6-1 -> 0.049261214 | I25: =I6/H6-1 -> 0.049285216 | J25: =J6/I6-1 -> 0.049309273 | K25: =K6/J6-1 -> 0.049333387 | L25: =L6/K6-1 -> 0.049357555
B26: Gross margin | D26: =D8/D6 -> 0.48011365 | E26: =E8/E6 -> 0.49819033 | F26: =F8/F6 -> 0.50132566 | G26: =G8/G6 -> 0.505 | H26: =H8/H6 -> 0.507 | I26: =I8/I6 -> 0.509 | J26: =J8/J6 -> 0.511 | K26: =K8/K6 -> 0.513 | L26: =L8/L6 -> 0.515
B27: Cost of sales (% of revenue) | D27: =-D7/D6 -> 0.51988635 | E27: =-E7/E6 -> 0.50180967 | F27: =-F7/F6 -> 0.49867434 | G27: =Inputs!G16 -> 0.495 | H27: =Inputs!H16 -> 0.493 | I27: =Inputs!I16 -> 0.491 | J27: =Inputs!J16 -> 0.489 | K27: =Inputs!K16 -> 0.487 | L27: =Inputs!L16 -> 0.485
B28: SG&A (% of revenue) | D28: =-D9/D6 -> 0.083994635 | E28: =-E9/E6 -> 0.077482192 | F28: =-F9/F6 -> 0.084045515 | G28: =Inputs!G17 -> 0.084 | H28: =Inputs!H17 -> 0.084 | I28: =Inputs!I17 -> 0.084 | J28: =Inputs!J17 -> 0.084 | K28: =Inputs!K17 -> 0.084 | L28: =Inputs!L17 -> 0.084
B29: R&D (% of revenue) | D29: =-D10/D6 -> 0.15221459 | E29: =-E10/E6 -> 0.14766121 | F29: =-F10/F6 -> 0.1339129 | G29: =Inputs!G18 -> 0.132 | H29: =Inputs!H18 -> 0.132 | I29: =Inputs!I18 -> 0.132 | J29: =Inputs!J18 -> 0.132 | K29: =Inputs!K18 -> 0.132 | L29: =Inputs!L18 -> 0.132
B30: Other expenses, net (% of revenue) | D30: =-D11/D6 -> 0.0042290335 | E30: =-E11/E6 -> 0.0031654167 | F30: =-F11/F6 -> 0.0018636541 | G30: =Inputs!G19 -> 0.002 | H30: =Inputs!H19 -> 0.002 | I30: =Inputs!I19 -> 0.002 | J30: =Inputs!J19 -> 0.002 | K30: =Inputs!K19 -> 0.002 | L30: =Inputs!L19 -> 0.002
B31: EBITDA margin | D31: =D23/D6 -> 0.34809001 | E31: =E23/E6 -> 0.3818456 | F31: =F23/F6 -> 0.38260522 | G31: =G23/G6 -> 0.38372404 | H31: =H23/H6 -> 0.38371335 | I31: =I23/I6 -> 0.38442478 | J31: =J23/J6 -> 0.38561651 | K31: =K23/K6 -> 0.38712425 | L31: =L23/L6 -> 0.388837
B32: EBIT margin | D32: =D13/D6 -> 0.2408873 | E32: =E13/E6 -> 0.27090946 | F32: =F13/F6 -> 0.28273849 | G32: =G13/G6 -> 0.28812566 | H32: =H13/H6 -> 0.29007281 | I32: =I13/I6 -> 0.29202242 | J32: =J13/J6 -> 0.29397438 | K32: =K13/K6 -> 0.29592857 | L32: =L13/L6 -> 0.29788489
B33: Effective tax rate | D33: =-D17/D16 -> 0.20247825 | E33: =-E17/E16 -> 0.21524395 | F33: =-F17/F16 -> 0.19219241 | G33: =Inputs!G21 -> 0.2 | H33: =Inputs!H21 -> 0.2 | I33: =Inputs!I21 -> 0.2 | J33: =Inputs!J21 -> 0.2 | K33: =Inputs!K21 -> 0.2 | L33: =Inputs!L21 -> 0.2
B34: Non-controlling interests (% of net profit) | D34: =D19/D18 -> 0.0071117243 | E34: =E19/E18 -> 0.0043015387 | F34: =F19/F18 -> 0.0026449739 | G34: =Inputs!G22 -> 0.003 | H34: =Inputs!H22 -> 0.003 | I34: =Inputs!I22 -> 0.003 | J34: =Inputs!J22 -> 0.003 | K34: =Inputs!K22 -> 0.003 | L34: =Inputs!L22 -> 0.003
B36: Revenue Build: Shipments and Revenue per Unit
B37: Shipments in units, revenue in € millions | F37: Actual | L37: Forecast
D38: =D$5 -> 2022 | E38: =E$5 -> 2023 | F38: =F$5 -> 2024 | G38: =G$5 -> 2025 | H38: =H$5 -> 2026 | I38: =I$5 -> 2027 | J38: =J$5 -> 2028 | K38: =K$5 -> 2029 | L38: =L$5 -> 2030
B39: SHIPMENTS BY REGION
B40: EMEA | D40: 5958 | E40: 6063 | F40: 6204 | G40: =F40*(1+Inputs!G9) -> 6266.04 | H40: =G40*(1+Inputs!H9) -> 6328.7004 | I40: =H40*(1+Inputs!I9) -> 6391.9874 | J40: =I40*(1+Inputs!J9) -> 6455.9073 | K40: =J40*(1+Inputs!K9) -> 6520.4664 | L40: =K40*(1+Inputs!L9) -> 6585.671
B41: Americas | D41: 3447 | E41: 3811 | F41: 4003 | G41: =F41*(1+Inputs!G10) -> 4083.06 | H41: =G41*(1+Inputs!H10) -> 4164.7212 | I41: =H41*(1+Inputs!I10) -> 4248.0156 | J41: =I41*(1+Inputs!J10) -> 4332.9759 | K41: =J41*(1+Inputs!K10) -> 4419.6355 | L41: =K41*(1+Inputs!L10) -> 4508.0282
B42: Mainland China, Hong Kong and Taiwan | D42: 1552 | E42: 1490 | F42: 1162 | G42: =F42*(1+Inputs!G11) -> 1185.24 | H42: =G42*(1+Inputs!H11) -> 1208.9448 | I42: =H42*(1+Inputs!I11) -> 1233.1237 | J42: =I42*(1+Inputs!J11) -> 1257.7862 | K42: =J42*(1+Inputs!K11) -> 1282.9419 | L42: =K42*(1+Inputs!L11) -> 1308.6007
...
